Workbook

Sheet A
A1: NOMBRE APELLIDO | B1: -2=EsBalada, -1=PareceBalada, 1=PareceRegeatton, 2=EsRegaetton | C1: FRAGMENTO DE LETRAS DE CANCIONES (ALREDEDOR DE 30+ PALABRAS)
A2: EDGAR CASASOLA | B2: -1 | C2: ¿A quién le mientes si en tu soledad? Quieres verme otra vez Por ti respondo lo que tú me das Lo que nadie sabe Me decido por ti, te decides por mí A la misma hora Me dan ganas de ti, te dan ganas de mí A la misma hora
A3: DANIEL SEQUEIRA APUY | B3: 2 | C3: ¿Cómo te llamas, baby? Desde que te vi supe que eras pa’ mí Dile a tus amigas que andamo' ready Esto lo seguimo' en el after party
A4: ESTEBAN HIGUERA | B4: -2 | C4: ¿Cómo te va, mi amor? ¿Cómo te va? Era en silencio la pregunta entre tú y yo ¿Eres feliz, mi bien? Sin engañar Porque a mi puerta el amor nunca volvió
A5: Adrian Arrieta Orozco | B5: 2 | C5: ¿Pa' qué buscar en la calle lo que abunda en mi casa? Una mamacita buena gente, qué chimba de cuerpo y de cara. Y aunque la baby es inocente y con otras se compara. Diosito la hizo humilde, pero yo la veo bien cara
A6: Andres Camacho | B6: 0 | C6: ¿Por qué sigues con él? (¿Por qué sigues con él?) Si borracha me confesaste que él no te lo hace bien Tú le calientas la comida, pero él no te sabe comer (okay) Si pruebas, no vas a volver (no), no, yeh
A7: DANIEL SEQUEIRA APUY | B7: 1 | C7: ¿Qué hace' tan triste y solita? Recuerdo, feliz, tu carita Me busca si me necesita Conmigo, te puede' desahogar
A8: Matias Casasola | B8: -1 | C8: ¿Qué más puedo decirte? Tal vez puedo mentirte sin razón Pero lo que hoy siento Es que sin ti, estoy muerto, pues eres Lo que más quiero en este mundo, eso eres
A9: DENNIS CAMACHO SOTO | B9: 2 | C9: ¿Qué me hizo usted? Que la quiero volver a ver Y volverla a besar Yo te paso a buscar, buscar Es que la bellaquera contigo Con nadie más la consigo De tus grito' hoy no me olvido Te-te-tengo reservao' el hotel
A10: IVAN RIOS BALTODANO | B10: -2 | C10: ¿Qué tienen tus ojos, tus labios, tu piel Que nunca se acaba esta luna de miel? Somos la copa y el vino Tú y yo vamos juntos desde que nos vimos Subimos, bajamos, lloramos, reímos Y es que contigo, mi amor, todo me sabe mejor
A11: DENNIS CAMACHO SOTO | B11: -2 | C11: ¿Y quién te escribirá poemas y cartas? ¿Y quién te contará sus miedos y faltas? ¿A quién le dejarás dormirse en tu espalda? Y luego en el silencio le dirás "te quiero" Detendrá su aliento sobre tu cara Perderá su rumbo en tu mirada Y se le olvidará la vida amándote ¿Ahora quién?
A12: KONSTANTIN LATYSH | B12: 1 | C12: "Ella no era así, ella no era así No sé quién la dañó Ella no era así, ella no era así No sé quién la dañó"
A13: Matias Casasola | B13: 2 | C13: (¿Pa' qué me estás llamando?) Dime si es verdad que él te trae loca (¿Y a vos qué te importa?) (¿Ah, sí?) Aún no lo creo, en tan poco tiempo y ya besas otra boca ¡De malas! (¿Qué?) Dime cuál fue mi error (dime) Si mi único delito solo fue amarte Hoy soy el perdedor (bebé, nomás) Y él me ha robado el truco para enamorarte (¿qué pasa, mi amor?)
... A691: Arturo Daniels Fernández | B691: 2 | C691: Zúmbale mambo, pa' que mis gatas prendan los motore' Zúmbale mambo, pa' que mis gatas prendan los motore' Zúmbale mambo, pa' que mis gatas prendan los motore' Que se preparen, que lo que viene es pa' que le den (¡duro!) Mamita, yo sé que tú no te me vas a quitar (¡duro!) Lo que me gusta es que tú te dejas llevar (¡duro!) Todos los weekend, ella sale a vacilar (¡duro!) Mi gata no para de janguear, porque

Sheet B
A1: NOMBRE APELLIDO | B1: -2=EsBalada, -1=PareceBalada, 1=PareceRegeatton, 2=EsRegaetton | C1: FRAGMENTO DE LETRAS DE CANCIONES (ALREDEDOR DE 30+ PALABRAS)
A2: MINOR SANDI | B2: -2 | C2: ¿A quién le mientes si en tu soledad? Quieres verme otra vez Por ti respondo lo que tú me das Lo que nadie sabe Me decido por ti, te decides por mí A la misma hora Me dan ganas de ti, te dan ganas de mí A la misma hora
A3: Sawyer Dixon | B3: 2 | C3: ¿Cómo te llamas, baby? Desde que te vi supe que eras pa’ mí Dile a tus amigas que andamo' ready Esto lo seguimo' en el after party
A4: Andres Camacho | B4: 0 | C4: ¿Cómo te va, mi amor? ¿Cómo te va? Era en silencio la pregunta entre tú y yo ¿Eres feliz, mi bien? Sin engañar Porque a mi puerta el amor nunca volvió
A5: EVAN CHEN | B5: 2 | C5: ¿Pa' qué buscar en la calle lo que abunda en mi casa? Una mamacita buena gente, qué chimba de cuerpo y de cara. Y aunque la baby es inocente y con otras se compara. Diosito la hizo humilde, pero yo la veo bien cara
A6: DENNIS CAMACHO SOTO | B6: 2 | C6: ¿Por qué sigues con él? (¿Por qué sigues con él?) Si borracha me confesaste que él no te lo hace bien Tú le calientas la comida, pero él no te sabe comer (okay) Si pruebas, no vas a volver (no), no, yeh
A7: Juan Pablo Vindas | B7: 0 | C7: ¿Qué hace' tan triste y solita? Recuerdo, feliz, tu carita Me busca si me necesita Conmigo, te puede' desahogar
A8: KONSTANTIN LATYSH | B8: -2 | C8: ¿Qué más puedo decirte? Tal vez puedo mentirte sin razón Pero lo que hoy siento Es que sin ti, estoy muerto, pues eres Lo que más quiero en este mundo, eso eres
A9: ENRIQUE RAMÍREZ | B9: 2 | C9: ¿Qué me hizo usted? Que la quiero volver a ver Y volverla a besar Yo te paso a buscar, buscar Es que la bellaquera contigo Con nadie más la consigo De tus grito' hoy no me olvido Te-te-tengo reservao' el hotel
A10: Juan Diego Gauthier Sandoval | B10: -2 | C10: ¿Qué tienen tus ojos, tus labios, tu piel Que nunca se acaba esta luna de miel? Somos la copa y el vino Tú y yo vamos juntos desde que nos vimos Subimos, bajamos, lloramos, reímos Y es que contigo, mi amor, todo me sabe mejor
A11: Sawyer Dixon | B11: -2 | C11: ¿Y quién te escribirá poemas y cartas? ¿Y quién te contará sus miedos y faltas? ¿A quién le dejarás dormirse en tu espalda? Y luego en el silencio le dirás "te quiero" Detendrá su aliento sobre tu cara Perderá su rumbo en tu mirada Y se le olvidará la vida amándote ¿Ahora quién?
A12: Arturo Daniels Fernández | B12: 1 | C12: "Ella no era así, ella no era así No sé quién la dañó Ella no era así, ella no era así No sé quién la dañó"
A13: Anabelle Porras Carrillo | B13: 2 | C13: (¿Pa' qué me estás llamando?) Dime si es verdad que él te trae loca (¿Y a vos qué te importa?) (¿Ah, sí?) Aún no lo creo, en tan poco tiempo y ya besas otra boca ¡De malas! (¿Qué?) Dime cuál fue mi error (dime) Si mi único delito solo fue amarte Hoy soy el perdedor (bebé, nomás) Y él me ha robado el truco para enamorarte (¿qué pasa, mi amor?)
... A691: Leonardo Sibaja Campos | B691: 2 | C691: Zúmbale mambo, pa' que mis gatas prendan los motore' Zúmbale mambo, pa' que mis gatas prendan los motore' Zúmbale mambo, pa' que mis gatas prendan los motore' Que se preparen, que lo que viene es pa' que le den (¡duro!) Mamita, yo sé que tú no te me vas a quitar (¡duro!) Lo que me gusta es que tú te dejas llevar (¡duro!) Todos los weekend, ella sale a vacilar (¡duro!) Mi gata no para de janguear, porque

Sheet C
A1: NOMBRE APELLIDO | B1: -2=EsBalada, -1=PareceBalada, 1=PareceRegeatton, 2=EsRegaetton | C1: FRAGMENTO DE LETRAS DE CANCIONES (ALREDEDOR DE 30+ PALABRAS)
A2: Arturo Daniels Fernández | B2: -1 | C2: ¿A quién le mientes si en tu soledad? Quieres verme otra vez Por ti respondo lo que tú me das Lo que nadie sabe Me decido por ti, te decides por mí A la misma hora Me dan ganas de ti, te dan ganas de mí A la misma hora
A3: IVAN RIOS BALTODANO | B3: 2 | C3: ¿Cómo te llamas, baby? Desde que te vi supe que eras pa’ mí Dile a tus amigas que andamo' ready Esto lo seguimo' en el after party
A4: EVAN CHEN | B4: -1 | C4: ¿Cómo te va, mi amor? ¿Cómo te va? Era en silencio la pregunta entre tú y yo ¿Eres feliz, mi bien? Sin engañar Porque a mi puerta el amor nunca volvió
A5: EDGAR CASASOLA | B5: 2 | C5: ¿Pa' qué buscar en la calle lo que abunda en mi casa? Una mamacita buena gente, qué chimba de cuerpo y de cara. Y aunque la baby es inocente y con otras se compara. Diosito la hizo humilde, pero yo la veo bien cara
A6: ENRIQUE RAMÍREZ | B6: 2 | C6: ¿Por qué sigues con él? (¿Por qué sigues con él?) Si borracha me confesaste que él no te lo hace bien Tú le calientas la comida, pero él no te sabe comer (okay) Si pruebas, no vas a volver (no), no, yeh
A7: Arturo Daniels Fernández | B7: 2 | C7: ¿Qué hace' tan triste y solita? Recuerdo, feliz, tu carita Me busca si me necesita Conmigo, te puede' desahogar
A8: Anthony Sanchez | B8: -2 | C8: ¿Qué más puedo decirte? Tal vez puedo mentirte sin razón Pero lo que hoy siento Es que sin ti, estoy muerto, pues eres Lo que más quiero en este mundo, eso eres
A9: Mauro Valenciano | B9: 2 | C9: ¿Qué me hizo usted? Que la quiero volver a ver Y volverla a besar Yo te paso a buscar, buscar Es que la bellaquera contigo Con nadie más la consigo De tus grito' hoy no me olvido Te-te-tengo reservao' el hotel
A10: Isabel Gómez | B10: -1 | C10: ¿Qué tienen tus ojos, tus labios, tu piel Que nunca se acaba esta luna de miel? Somos la copa y el vino Tú y yo vamos juntos desde que nos vimos Subimos, bajamos, lloramos, reímos Y es que contigo, mi amor, todo me sabe mejor
A11: ESTEBAN ROMÁN OVIEDO | B11: 0 | C11: ¿Y quién te escribirá poemas y cartas? ¿Y quién te contará sus miedos y faltas? ¿A quién le dejarás dormirse en tu espalda? Y luego en el silencio le dirás "te quiero" Detendrá su aliento sobre tu cara Perderá su rumbo en tu mirada Y se le olvidará la vida amándote ¿Ahora quién?
A12: Anabelle Porras Carrillo | B12: -1 | C12: "Ella no era así, ella no era así No sé quién la dañó Ella no era así, ella no era así No sé quién la dañó"
A13: BRANDON PALACIOS DELGADO | B13: 2 | C13: (¿Pa' qué me estás llamando?) Dime si es verdad que él te trae loca (¿Y a vos qué te importa?) (¿Ah, sí?) Aún no lo creo, en tan poco tiempo y ya besas otra boca ¡De malas! (¿Qué?) Dime cuál fue mi error (dime) Si mi único delito solo fue amarte Hoy soy el perdedor (bebé, nomás) Y él me ha robado el truco para enamorarte (¿qué pasa, mi amor?)
... A691: LUIS ARIAS GÓMEZ | B691: 2 | C691: Zúmbale mambo, pa' que mis gatas prendan los motore' Zúmbale mambo, pa' que mis gatas prendan los motore' Zúmbale mambo, pa' que mis gatas prendan los motore' Que se preparen, que lo que viene es pa' que le den (¡duro!) Mamita, yo sé que tú no te me vas a quitar (¡duro!) Lo que me gusta es que tú te dejas llevar (¡duro!) Todos los weekend, ella sale a vacilar (¡duro!) Mi gata no para de janguear, porque

Sheet AGREEMENT
A1: CATEGORIA | B1: AGREEMENT SCORE | C1: =A!A1 -> NOMBRE APELLIDO | D1: =A!B1 -> -2=EsBalada, -1=PareceBalada, 1=PareceRegeatton, 2=EsRegaetton | E1: =A!C1 -> FRAGMENTO DE LETRAS DE CANCIONES (ALREDEDOR DE 30+ PALABRAS) | F1: =B!A1 -> NOMBRE APELLIDO | G1: =B!B1 -> -2=EsBalada, -1=PareceBalada, 1=PareceRegeatton, 2=EsRegaetton | H1: =B!C1 -> FRAGMENTO DE LETRAS DE CANCIONES (ALREDEDOR DE 30+ PALABRAS) | I1: ='C'!A1 -> NOMBRE APELLIDO | J1: ='C'!B1 -> -2=EsBalada, -1=PareceBalada, 1=PareceRegeatton, 2=EsRegaetton | K1: ='C'!C1 -> FRAGMENTO DE LETRAS DE CANCIONES (ALREDEDOR DE 30+ PALABRAS) | L1: EXTRA | M1: CRITERIO | N1: VOTO EXTRA
A2: =IF(B2>0,"REGAETTON","BALADA") -> BALADA | B2: =SUM(D2,G2,J2,N2) -> -4 | C2: =A!A2 -> EDGAR CASASOLA | D2: =A!B2 -> -1 | E2: =A!C2 -> ¿A quién le mientes si en tu soledad? Quieres verme otra vez Por ti respondo lo que tú me das Lo que nadie sabe Me decido por ti, te decides por mí A la misma hora Me dan ganas de ti, te dan ganas de mí A la misma hora | F2: =B!A2 -> MINOR SANDI | G2: =B!B2 -> -2 | H2: =B!C2 -> ¿A quién le mientes si en tu soledad? Quieres verme otra vez Por ti respondo lo que tú me das Lo que nadie sabe Me decido por ti, te decides por mí A la misma hora Me dan ganas de ti, te dan ganas de mí A la misma hora | I2: ='C'!A2 -> Arturo Daniels Fernández | J2: ='C'!B2 -> -1 | K2: ='C'!C2 -> ¿A quién le mientes si en tu soledad? Quieres verme otra vez Por ti respondo lo que tú me das Lo que nadie sabe Me decido por ti, te decides por mí A la misma hora Me dan ganas de ti, te dan ganas de mí A la misma hora | M2: =IF(B2=0,"X"," ") | N2: 0
A3: =IF(B3>0,"REGAETTON","BALADA") -> REGAETTON | B3: =SUM(D3,G3,J3,N3) -> 6 | C3: =A!A3 -> DANIEL SEQUEIRA APUY | D3: =A!B3 -> 2 | E3: =A!C3 -> ¿Cómo te llamas, baby? Desde que te vi supe que eras pa’ mí Dile a tus amigas que andamo' ready Esto lo seguimo' en el after party | F3: =B!A3 -> Sawyer Dixon | G3: =B!B3 -> 2 | H3: =B!C3 -> ¿Cómo te llamas, baby? Desde que te vi supe que eras pa’ mí Dile a tus amigas que andamo' ready Esto lo seguimo' en el after party | I3: ='C'!A3 -> IVAN RIOS BALTODANO | J3: ='C'!B3 -> 2 | K3: ='C'!C3 -> ¿Cómo te llamas, baby? Desde que te vi supe que eras pa’ mí Dile a tus amigas que andamo' ready Esto lo seguimo' en el after party | M3: =IF(B3=0,"X"," ") | N3: 0
A4: =IF(B4>0,"REGAETTON","BALADA") -> BALADA | B4: =SUM(D4,G4,J4,N4) -> -3 | C4: =A!A4 -> ESTEBAN HIGUERA | D4: =A!B4 -> -2 | E4: =A!C4 -> ¿Cómo te va, mi amor? ¿Cómo te va? Era en silencio la pregunta entre tú y yo ¿Eres feliz, mi bien? Sin engañar Porque a mi puerta el amor nunca volvió | F4: =B!A4 -> Andres Camacho | G4: =B!B4 -> 0 | H4: =B!C4 -> ¿Cómo te va, mi amor? ¿Cómo te va? Era en silencio la pregunta entre tú y yo ¿Eres feliz, mi bien? Sin engañar Porque a mi puerta el amor nunca volvió | I4: ='C'!A4 -> EVAN CHEN | J4: ='C'!B4 -> -1 | K4: ='C'!C4 -> ¿Cómo te va, mi amor? ¿Cómo te va? Era en silencio la pregunta entre tú y yo ¿Eres feliz, mi bien? Sin engañar Porque a mi puerta el amor nunca volvió | M4: =IF(B4=0,"X"," ") | N4: 0
A5: =IF(B5>0,"REGAETTON","BALADA") -> REGAETTON | B5: =SUM(D5,G5,J5,N5) -> 6 | C5: =A!A5 -> Adrian Arrieta Orozco | D5: =A!B5 -> 2 | E5: =A!C5 -> ¿Pa' qué buscar en la calle lo que abunda en mi casa? Una mamacita buena gente, qué chimba de cuerpo y de cara. Y aunque la baby es inocente y con otras se compara. Diosito la hizo humilde, pero yo la veo bien cara | F5: =B!A5 -> EVAN CHEN | G5: =B!B5 -> 2 | H5: =B!C5 -> ¿Pa' qué buscar en la calle lo que abunda en mi casa? Una mamacita buena gente, qué chimba de cuerpo y de cara. Y aunque la baby es inocente y con otras se compara. Diosito la hizo humilde, pero yo la veo bien cara | I5: ='C'!A5 -> EDGAR CASASOLA | J5: ='C'!B5 -> 2 | K5: ='C'!C5 -> ¿Pa' qué buscar en la calle lo que abunda en mi casa? Una mamacita buena gente, qué chimba de cuerpo y de cara. Y aunque la baby es inocente y con otras se compara. Diosito la hizo humilde, pero yo la veo bien cara | M5: =IF(B5=0,"X"," ") | N5: 0
A6: =IF(B6>0,"REGAETTON","BALADA") -> REGAETTON | B6: =SUM(D6,G6,J6,N6) -> 4 | C6: =A!A6 -> Andres Camacho | D6: =A!B6 -> 0 | E6: =A!C6 -> ¿Por qué sigues con él? (¿Por qué sigues con él?) Si borracha me confesaste que él no te lo hace bien Tú le calientas la comida, pero él no te sabe comer (okay) Si pruebas, no vas a volver (no), no, yeh | F6: =B!A6 -> DENNIS CAMACHO SOTO | G6: =B!B6 -> 2 | H6: =B!C6 -> ¿Por qué sigues con él? (¿Por qué sigues con él?) Si borracha me confesaste que él no te lo hace bien Tú le calientas la comida, pero él no te sabe comer (okay) Si pruebas, no vas a volver (no), no, yeh | I6: ='C'!A6 -> ENRIQUE RAMÍREZ | J6: ='C'!B6 -> 2 | K6: ='C'!C6 -> ¿Por qué sigues con él? (¿Por qué sigues con él?) Si borracha me confesaste que él no te lo hace bien Tú le calientas la comida, pero él no te sabe comer (okay) Si pruebas, no vas a volver (no), no, yeh | M6: =IF(B6=0,"X"," ") | N6: 0
A7: =IF(B7>0,"REGAETTON","BALADA") -> REGAETTON | B7: =SUM(D7,G7,J7,N7) -> 3 | C7: =A!A7 -> DANIEL SEQUEIRA APUY | D7: =A!B7 -> 1 | E7: =A!C7 -> ¿Qué hace' tan triste y solita? Recuerdo, feliz, tu carita Me busca si me necesita Conmigo, te puede' desahogar | F7: =B!A7 -> Juan Pablo Vindas | G7: =B!B7 -> 0 | H7: =B!C7 -> ¿Qué hace' tan triste y solita? Recuerdo, feliz, tu carita Me busca si me necesita Conmigo, te puede' desahogar | I7: ='C'!A7 -> Arturo Daniels Fernández | J7: ='C'!B7 -> 2 | K7: ='C'!C7 -> ¿Qué hace' tan triste y solita? Recuerdo, feliz, tu carita Me busca si me necesita Conmigo, te puede' desahogar | M7: =IF(B7=0,"X"," ") | N7: 0
A8: =IF(B8>0,"REGAETTON","BALADA") -> BALADA | B8: =SUM(D8,G8,J8,N8) -> -5 | C8: =A!A8 -> Matias Casasola | D8: =A!B8 -> -1 | E8: =A!C8 -> ¿Qué más puedo decirte? Tal vez puedo mentirte sin razón Pero lo que hoy siento Es que sin ti, estoy muerto, pues eres Lo que más quiero en este mundo, eso eres | F8: =B!A8 -> KONSTANTIN LATYSH | G8: =B!B8 -> -2 | H8: =B!C8 -> ¿Qué más puedo decirte? Tal vez puedo mentirte sin razón Pero lo que hoy siento Es que sin ti, estoy muerto, pues eres Lo que más quiero en este mundo, eso eres | I8: ='C'!A8 -> Anthony Sanchez | J8: ='C'!B8 -> -2 | K8: ='C'!C8 -> ¿Qué más puedo decirte? Tal vez puedo mentirte sin razón Pero lo que hoy siento Es que sin ti, estoy muerto, pues eres Lo que más quiero en este mundo, eso eres | M8: =IF(B8=0,"X"," ") | N8: 0
A9: =IF(B9>0,"REGAETTON","BALADA") -> REGAETTON | B9: =SUM(D9,G9,J9,N9) -> 6 | C9: =A!A9 -> DENNIS CAMACHO SOTO | D9: =A!B9 -> 2 | E9: =A!C9 -> ¿Qué me hizo usted? Que la quiero volver a ver Y volverla a besar Yo te paso a buscar, buscar Es que la bellaquera contigo Con nadie más la consigo De tus grito' hoy no me olvido Te-te-tengo reservao' el hotel | F9: =B!A9 -> ENRIQUE RAMÍREZ | G9: =B!B9 -> 2 | H9: =B!C9 -> ¿Qué me hizo usted? Que la quiero volver a ver Y volverla a besar Yo te paso a buscar, buscar Es que la bellaquera contigo Con nadie más la consigo De tus grito' hoy no me olvido Te-te-tengo reservao' el hotel | I9: ='C'!A9 -> Mauro Valenciano | J9: ='C'!B9 -> 2 | K9: ='C'!C9 -> ¿Qué me hizo usted? Que la quiero volver a ver Y volverla a besar Yo te paso a buscar, buscar Es que la bellaquera contigo Con nadie más la consigo De tus grito' hoy no me olvido Te-te-tengo reservao' el hotel | M9: =IF(B9=0,"X"," ") | N9: 0
A10: =IF(B10>0,"REGAETTON","BALADA") -> BALADA | B10: =SUM(D10,G10,J10,N10) -> -5 | C10: =A!A10 -> IVAN RIOS BALTODANO | D10: =A!B10 -> -2 | E10: =A!C10 -> ¿Qué tienen tus ojos, tus labios, tu piel Que nunca se acaba esta luna de miel? Somos la copa y el vino Tú y yo vamos juntos desde que nos vimos Subimos, bajamos, lloramos, reímos Y es que contigo, mi amor, todo me sabe mejor | F10: =B!A10 -> Juan Diego Gauthier Sandoval | G10: =B!B10 -> -2 | H10: =B!C10 -> ¿Qué tienen tus ojos, tus labios, tu piel Que nunca se acaba esta luna de miel? Somos la copa y el vino Tú y yo vamos juntos desde que nos vimos Subimos, bajamos, lloramos, reímos Y es que contigo, mi amor, todo me sabe mejor | I10: ='C'!A10 -> Isabel Gómez | J10: ='C'!B10 -> -1 | K10: ='C'!C10 -> ¿Qué tienen tus ojos, tus labios, tu piel Que nunca se acaba esta luna de miel? Somos la copa y el vino Tú y yo vamos juntos desde que nos vimos Subimos, bajamos, lloramos, reímos Y es que contigo, mi amor, todo me sabe mejor | M10: =IF(B10=0,"X"," ") | N10: 0
A11: =IF(B11>0,"REGAETTON","BALADA") -> BALADA | B11: =SUM(D11,G11,J11,N11) -> -4 | C11: =A!A11 -> DENNIS CAMACHO SOTO | D11: =A!B11 -> -2 | E11: =A!C11 -> ¿Y quién te escribirá poemas y cartas? ¿Y quién te contará sus miedos y faltas? ¿A quién le dejarás dormirse en tu espalda? Y luego en el silencio le dirás "te quiero" Detendrá su aliento sobre tu cara Perderá su rumbo en tu mirada Y se le olvidará la vida amándote ¿Ahora quién? | F11: =B!A11 -> Sawyer Dixon | G11: =B!B11 -> -2 | H11: =B!C11 -> ¿Y quién te escribirá poemas y cartas? ¿Y quién te contará sus miedos y faltas? ¿A quién le dejarás dormirse en tu espalda? Y luego en el silencio le dirás "te quiero" Detendrá su aliento sobre tu cara Perderá su rumbo en tu mirada Y se le olvidará la vida amándote ¿Ahora quién? | I11: ='C'!A11 -> ESTEBAN ROMÁN OVIEDO | J11: ='C'!B11 -> 0 | K11: ='C'!C11 -> ¿Y quién te escribirá poemas y cartas? ¿Y quién te contará sus miedos y faltas? ¿A quién le dejarás dormirse en tu espalda? Y luego en el silencio le dirás "te quiero" Detendrá su aliento sobre tu cara Perderá su rumbo en tu mirada Y se le olvidará la vida amándote ¿Ahora quién? | M11: =IF(B11=0,"X"," ") | N11: 0
A12: =IF(B12>0,"REGAETTON","BALADA") -> REGAETTON | B12: =SUM(D12,G12,J12,N12) -> 1 | C12: =A!A12 -> KONSTANTIN LATYSH | D12: =A!B12 -> 1 | E12: =A!C12 -> "Ella no era así, ella no era así No sé quién la dañó Ella no era así, ella no era así No sé quién la dañó" | F12: =B!A12 -> Arturo Daniels Fernández | G12: =B!B12 -> 1 | H12: =B!C12 -> "Ella no era así, ella no era así No sé quién la dañó Ella no era así, ella no era así No sé quién la dañó" | I12: ='C'!A12 -> Anabelle Porras Carrillo | J12: ='C'!B12 -> -1 | K12: ='C'!C12 -> "Ella no era así, ella no era así No sé quién la dañó Ella no era así, ella no era así No sé quién la dañó" | M12: =IF(B12=0,"X"," ") | N12: 0
A13: =IF(B13>0,"REGAETTON","BALADA") -> REGAETTON | B13: =SUM(D13,G13,J13,N13) -> 6 | C13: =A!A13 -> Matias Casasola | D13: =A!B13 -> 2 | E13: =A!C13 -> (¿Pa' qué me estás llamando?) Dime si es verdad que él te trae loca (¿Y a vos qué te importa?) (¿Ah, sí?) Aún no lo creo, en tan poco tiempo y ya besas otra boca ¡De malas! (¿Qué?) Dime cuál fue mi error (dime) Si mi único delito solo fue amarte Hoy soy el perdedor (bebé, nomás) Y él me ha robado el truco para enamorarte (¿qué pasa, mi amor?) | F13: =B!A13 -> Anabelle Porras Carrillo | G13: =B!B13 -> 2 | H13: =B!C13 -> (¿Pa' qué me estás llamando?) Dime si es verdad que él te trae loca (¿Y a vos qué te importa?) (¿Ah, sí?) Aún no lo creo, en tan poco tiempo y ya besas otra boca ¡De malas! (¿Qué?) Dime cuál fue mi error (dime) Si mi único delito solo fue amarte Hoy soy el perdedor (bebé, nomás) Y él me ha robado el truco para enamorarte (¿qué pasa, mi amor?) | I13: ='C'!A13 -> BRANDON PALACIOS DELGADO | J13: ='C'!B13 -> 2 | K13: ='C'!C13 -> (¿Pa' qué me estás llamando?) Dime si es verdad que él te trae loca (¿Y a vos qué te importa?) (¿Ah, sí?) Aún no lo creo, en tan poco tiempo y ya besas otra boca ¡De malas! (¿Qué?) Dime cuál fue mi error (dime) Si mi único delito solo fue amarte Hoy soy el perdedor (bebé, nomás) Y él me ha robado el truco para enamorarte (¿qué pasa, mi amor?) | M13: =IF(B13=0,"X"," ") | N13: 0
... A691: =IF(B691>0,"REGAETTON","BALADA") -> REGAETTON | B691: =SUM(D691,G691,J691,N691) -> 6 | C691: =A!A691 -> Arturo Daniels Fernández | D691: =A!B691 -> 2 | E691: =A!C691 -> Zúmbale mambo, pa' que mis gatas prendan los motore' Zúmbale mambo, pa' que mis gatas prendan los motore' Zúmbale mambo, pa' que mis gatas prendan los motore' Que se preparen, que lo que viene es pa' que le den (¡duro!) Mamita, yo sé que tú no te me vas a quitar (¡duro!) Lo que me gusta es que tú te dejas llevar (¡duro!) Todos los weekend, ella sale a vacilar (¡duro!) Mi gata no para de janguear, porque | F691: =B!A691 -> Leonardo Sibaja Campos | G691: =B!B691 -> 2 | H691: =B!C691 -> Zúmbale mambo, pa' que mis gatas prendan los motore' Zúmbale mambo, pa' que mis gatas prendan los motore' Zúmbale mambo, pa' que mis gatas prendan los motore' Que se preparen, que lo que viene es pa' que le den (¡duro!) Mamita, yo sé que tú no te me vas a quitar (¡duro!) Lo que me gusta es que tú te dejas llevar (¡duro!) Todos los weekend, ella sale a vacilar (¡duro!) Mi gata no para de janguear, porque | I691: ='C'!A691 -> LUIS ARIAS GÓMEZ | J691: ='C'!B691 -> 2 | K691: ='C'!C691 -> Zúmbale mambo, pa' que mis gatas prendan los motore' Zúmbale mambo, pa' que mis gatas prendan los motore' Zúmbale mambo, pa' que mis gatas prendan los motore' Que se preparen, que lo que viene es pa' que le den (¡duro!) Mamita, yo sé que tú no te me vas a quitar (¡duro!) Lo que me gusta es que tú te dejas llevar (¡duro!) Todos los weekend, ella sale a vacilar (¡duro!) Mi gata no para de janguear, porque | M691: =IF(B691=0,"X"," ") | N691: 0
B692: =COUNTIF(B1:B691,0) -> 0 | C692: =A!A692 | D692: =A!B692 | E692: =A!C692 | F692: =B!A692 | G692: =B!B692 | H692: =B!C692 | I692: ='C'!A692 | J692: ='C'!B692 | K692: ='C'!C692 | M692: =IF(B692=0,"X"," ") -> X | N692: 0
C693: =A!A693 | D693: =A!B693 | E693: =A!C693 | F693: =B!A693 | G693: =B!B693 | H693: =B!C693 | I693: ='C'!A693 | J693: ='C'!B693 | K693: ='C'!C693
C694: =A!A694 | D694: =A!B694 | E694: =A!C694 | F694: =B!A694 | G694: =B!B694 | H694: =B!C694 | I694: ='C'!A694 | J694: ='C'!B694 | K694: ='C'!C694
C695: =A!A695 | D695: =A!B695 | E695: =A!C695 | F695: =B!A695 | G695: =B!B695 | H695: =B!C695 | I695: ='C'!A695 | J695: ='C'!B695 | K695: ='C'!C695
C696: =A!A696 | D696: =A!B696 | E696: =A!C696 | F696: =B!A696 | G696: =B!B696 | H696: =B!C696 | I696: ='C'!A696 | J696: ='C'!B696 | K696: ='C'!C696

Sheet Entrenamiento
A1: =AGREEMENT!A1 -> CATEGORIA | B1: =AGREEMENT!E1 -> FRAGMENTO DE LETRAS DE CANCIONES (ALREDEDOR DE 30+ PALABRAS)
A2: =AGREEMENT!A606 -> BALADA | B2: =AGREEMENT!E606 -> Vuelve a mí Que solo y triste me quedé sin ti Y vivo sin hallar a quien querer Escúchame, mi amor Vuelve a mí Que solo y triste me quedé sin ti Y vivo sin hallar a quien querer Escúchame, mi amor
A3: =AGREEMENT!A488 -> BALADA | B3: =AGREEMENT!E488 -> Si aún no me lo crees, amor Y quieres, tú, correr el riesgo Verás que soy realmente bueno en engañar Y hacer sufrir y hacer llorar A quien más quiero, uoh-oh, uoh-oh, uoh-oh-oh
A4: =AGREEMENT!A411 -> BALADA | B4: =AGREEMENT!E411 -> Por cada beso tuyo Un sufrimiento recibí sin merecerlo No quise hacerle caso al corazón Que fue el primero en comprenderlo Ya sentí, ya comprendí que no me quieres Que seré juguete vil de tus placeres
A5: =AGREEMENT!A319 -> REGAETTON | B5: =AGREEMENT!E319 -> Mi bicho anda fugao' y yo quiero que tú me lo esconda' Agárralo como bonga Se metió una pepa que la pone cachonda Chinga en lo' Audi, no en lo' Honda Ey, si te lo meto no me llame' Que esto no es pa' que me ame', ey Si tu novio no te mama el culo Pa' eso que no mame Baja pa' casa que yo te lambo toa' Mami, yo te lambo toa' Baja pa' casa que yo te rompo toa', ey Que yo te rompo toa' Baja pa' casa que yo te lambo toa' (sigue) Mami, yo te lambo toa' (sigue) Dime, sierva (papi, sigue) Si tú fumas yerba (papi, pa-pa)
A6: =AGREEMENT!A53 -> REGAETTON | B6: =AGREEMENT!E53 -> Aquí pasamos moñas por el TSA Las putas se montan fácil como en GTA 200 cajas 'e paper que pedí en eBay En PR ya es legal, yo firmé la ley Fumando como Snoop Dogg y Wiz Kha Las gatas quieren Kush, no quieren Friska Prendí un bastón como el de la brisca
A7: =AGREEMENT!A306 -> REGAETTON | B7: =AGREEMENT!E306 -> Me gusta como a ti te cabe Si vamo' a culia hasta me habla en clave De ese tonton tengo la llave De ese planetita tengo nave Esque 'ta caliente y me llama pa' chinga'
A8: =AGREEMENT!A48 -> BALADA | B8: =AGREEMENT!E48 -> Antes que pase más Tiempo contigo amor Tengo que decir que eres el amor de mi vida Antes que te ame más Escucha por favor Déjame decir que todo te di Y no hay cómo explicar Pero, menos notar Simplemente, así lo sentí Cuando te vi (Wooh)
A9: =AGREEMENT!A353 -> BALADA | B9: =AGREEMENT!E353 -> No me platiques más Lo que debió pasar Antes de conocernos Sé que has tenido, horas felices Aún sin estar conmigo No quiero yo saber Qué pudo suceder En todos estos años Que tú has vivido con otras gentes Lejos de mi cariño
A10: =AGREEMENT!A686 -> REGAETTON | B10: =AGREEMENT!E686 -> Yo soy el cacique en tu propia aldea. Valgo más que todo lo que te rodea. No te la crea, recuerda que Curry la mete. Hasta que LeBron lo gardea. Baja pa' la cuesta. Que ando con la orquesta. Cabrón, no es la sexta. Yo nunca estoy abajo en las apuestas
A11: =AGREEMENT!A503 -> BALADA | B11: =AGREEMENT!E503 -> Si tú no vuelves. Se secarán todos los mares. Y esperaré sin ti. Tapiado al fondo de algún recuerdo. Si tú no vuelves. Mi voluntad se hará pequeña. Me quedaré aquí. Junto a mi perro, espiando horizontes. Si tú no vuelves. No quedarán más que desiertos. Y escucharé por si algún latido le queda a esta tierra
A12: =AGREEMENT!A339 -> REGAETTON | B12: =AGREEMENT!E339 -> Ni amigos, ni amantes Ni allegados, ni distantes ¿Qué eres mía y qué soy tuyo? Un fucking polvo que alimenta el orgullo ¿Quién es el que viene cuando el otro se va? Jugando a la mentira con besos de verdad
A13: =AGREEMENT!A635 -> REGAETTON | B13: =AGREEMENT!E635 -> Y si te vas, yo también me voy. No me dejes solo aquí esperando tu llamada. Ey, baby, tú eres la que manda en este bloque.
A14: =AGREEMENT!A154 -> REGAETTON | B14: =AGREEMENT!E154 -> Dos mil, loubutin los tacones
A15: =AGREEMENT!A609 -> REGAETTON | B15: =AGREEMENT!E609 -> Y a veces es Dolce, a veces Bulgari Cuando te lo quito después de los parties Las copas de vino, las libras de mari Tú estás bien suelta, yo de safari Tú mueve' el culo fenomenal Pa' yo devorarte como animal Si no te has vení'o, yo te vo' a esperar En mi cama y lo vo' a celebra
A16: =AGREEMENT!A631 -> REGAETTON | B16: =AGREEMENT!E631 -> Y que los tragos, hicieron estrago' en su cabeza. Ella con cualquiera no se besa, quiero que sepa que me interesa y no hay un día que no pare de pensar en su belleza.
A17: =AGREEMENT!A179 -> REGAETTON | B17: =AGREEMENT!E179 -> Ella no es normal Ella me lleva a la altura Chula ven chula Fuera del planeta ella es Chula ven chula Fuera del planeta ella es Chula ven chula Fuera del planeta ella es
A18: =AGREEMENT!A671 -> BALADA | B18: =AGREEMENT!E671 -> Yo no sé mañana, yo no sé mañana Si estaremos juntos, si se acaba el mundo Yo no sé si soy para ti, si serás para mí Si lleguemos a amarnos u odiarnos
A19: =AGREEMENT!A543 -> REGAETTON | B19: =AGREEMENT!E543 -> Te voy a explicar, empiezo con la A voy liberal, superar, llegar y triunfar y sin limitar y sin limitar, original rimar, improvisar, parar jamás llama a la fama, drama
A20: =AGREEMENT!A390 -> BALADA | B20: =AGREEMENT!E390 -> Para amarte Necesito una razón Y es difícil creer Que no exista una más que este amor Sobra tanto Dentro de este corazón Que a pesar de que dicen que los años son sabios Todavía se siente el dolor Porque todo el tiempo que pasé junto a ti Dejó tejido su hilo dentro de mí
A21: =AGREEMENT!A96 -> REGAETTON | B21: =AGREEMENT!E96 -> Casi siempre me llama a las 3 de la mañana Dice que soy su pana El que te quita las ganas Hemos hecho de to' Muchas posiciones en la escalera Amarrao en la cama Yo encima de ella Amanecimos en la bañera Y me la comí embarra’ de nutella
A22: =AGREEMENT!A485 -> BALADA | B22: =AGREEMENT!E485 -> Se te olvida, que me quieres a pesar de lo que dices. Pues llevamos en el alma cicatrices, imposibles de borrar, se te olvida, que hasta puedo hacerte mal si me decido. Pues tu amor lo tengo muy comprometido. Pero a fuerzas no será, y hoy resulta, que no soy de la estatura de tu vida. Y al dejarme casi, casi, se te olvida. Que hay un pacto entre los dos.
A23: =AGREEMENT!A246 -> BALADA | B23: =AGREEMENT!E246 -> Hoy le doy gracias al cielo por las veces que me equivoqué Y porque te encontré Me devolviste la fe, me presentaste a Cupido Y ahora parcho con él El brillo de los ojos se me nota Y los que me conocen saben que me curé Porque ahora ando en otra He dejado el whisky por usted
A24: =AGREEMENT!A172 -> REGAETTON | B24: =AGREEMENT!E172 -> Ella casi ni sale La traicionó el amor Tiene par de amistades Pero no quiere relación Donde va sobresale En sus ojos se ve la ilusión Pero llamó su amiga Que se olvide que esta es su canción Y baila, baila, baila Ponle música pa que esto no pare Baila, baila, baila Tengo que besarte antes que se acabe
A25: =AGREEMENT!A435 -> BALADA | B25: =AGREEMENT!E435 -> Que jamás imaginaste. Que llegaríamos hasta hoy. Que es mejor terminar todo. Para que no sufra tu amor. Lo hubieras pensado cuando me miraste. Con esa sonrisa que me hizo temblar. Y antes de decir la frase. Que me hizo sentir que yo era algo especial. Antes de que con tu suéter. Quitaras el frío de mi soledad. Antes de robarme un beso. Y encender mi cuerpo y no poder parar. No querías lastimarme. No querías lastimarme. ¡Me querías matar!
A26: =AGREEMENT!A30 -> BALADA | B26: =AGREEMENT!E30 -> Amar es cuando la proteges De la lluvia y el viento Amar es cuando tú la abrazas Y te olvidas del tiempo Amar es cuando tú la ves Y te pones nervioso Amar es cuando te das cuenta De tus sentimientos Por amarte robaría una estrella Y te la regalaría Por amarte cruzaría los mares Solo por abrazarte
A27: =AGREEMENT!A462 -> REGAETTON | B27: =AGREEMENT!E462 -> Quiero sacarte pa la calle y que pregunten to los compa' De dónde saqué esa porno star Es que con una baby así cualquiera ronca Que te presuman, no te gusta que te escondan, no Este bandido ya se retiró El que quería contigo se jodió Es que son muchas cosas juntas Y si se preguntan, ese culo lo tengo yo
A28: =AGREEMENT!A283 -> REGAETTON | B28: =AGREEMENT!E283 -> Los recuerdos de mi infancia son muy bellos fuimos pobres sin riquezas ni dinero pero a dios cada mañana le agradezco que por madre me mando un ángel del cielo.
A29: =AGREEMENT!A168 -> BALADA | B29: =AGREEMENT!E168 -> Él me mintió, él me mintió. Era un juego y nada más. Era solo un juego cruel de su vanidad. Él me mintió. Con el corazón destrozado Y el rostro mojado. Soy tan desdichada, quisiera morirme. Mentiras, todo era mentira. Palabras al viento. Tan solo un capricho que el niño tenía
A30: =AGREEMENT!A70 -> REGAETTON | B30: =AGREEMENT!E70 -> Ayer me besaste y no podías parar Y me bailaste hasta el amanecer Cuando desperté yo te quise llamar Y ahora me dice que borró cassete Que no se acuerda de esa noche Porque ella borró cassette Dice que no me conoce Y quiero volverla ver
A31: =AGREEMENT!A210 -> BALADA | B31: =AGREEMENT!E210 -> Esta historia terminó, no existe Lo que un día construimos, se ha esfumado Pareciera que es más fácil dejarnos Pero eres un fantasma conmigo caminando
A32: =AGREEMENT!A247 -> BALADA | B32: =AGREEMENT!E247 -> Hoy mi playa se viste de amargura, oh Porque tu barca tiene que partir A cruzar otros mares de locura Cuida que no naufrague en tu vivir Cuando la luz del sol se esté apagando y Te sientas cansada de vagar Piensa que yo por ti estaré esperando Hasta que tú decidas regresar
A33: =AGREEMENT!A236 -> BALADA | B33: =AGREEMENT!E236 -> Hasta que me olvides, voy a intentarlo No habrá quién me seque tus labios por dentro y por fuera No habrá quién desnude mi nombre una tarde cualquiera Hasta que me olvides tanto que No exista mañana ni después, no, no Hasta que me olvides, voy a intentarlo No habrá quién desnude mi boca como tu sonrisa Y voy a rodar como lágrima entre la llovizna Hasta que me olvides tanto que No exista mañana ni después
A34: =AGREEMENT!A610 -> REGAETTON | B34: =AGREEMENT!E610 -> Y a veces es Dolce, a veces Bulgari Cuando te lo quito después de los parties Las copas de vino, las libras de mari Tú estás bien suelta, yo de safari Tú mueve' el culo fenomenal Pa' yo devorarte como animal Si no te has vení'o, yo te vo'a esperar En mi cama y lo vo' a celebrar
A35: =AGREEMENT!A537 -> BALADA | B35: =AGREEMENT!E537 -> Te hiciste indispensable para mí, y, y Y con los ojos cerrados te seguí Si yo busqué dolor, lo conseguí No eres la persona que pensé Que creí, que pedí
A36: =AGREEMENT!A292 -> BALADA | B36: =AGREEMENT!E292 -> Me abrazaría al diablo sin dudar Por ver tu cara al escucharme hablar Eres todo lo que más quiero Pero te pierdo en mis silencios Mis ojos son dos cruces negras
A37: =AGREEMENT!A140 -> REGAETTON | B37: =AGREEMENT!E140 -> Dembow y reggaeton, mami, llégale a la mezcla y dale pa'l hotel, trae una amiga extra pónteme fresca como Carmen Electra y yo les doy corriente de la forma correcta
A38: =AGREEMENT!A176 -> BALADA | B38: =AGREEMENT!E176 -> Ella es un escándalo Ella te quita el oxígeno Es una obra de arte, ella es punto y aparte Ella es feliz con lo básico Y si la vieras bailando Lento, es un espectáculo Cómo piensa es brillante, ella es impresionante Todo en ella es romántico
A39: =AGREEMENT!A144 -> BALADA | B39: =AGREEMENT!E144 -> Después correr felices cara al viento, caernos en la arena, ya sin aliento. y tú en un suspiro tú, en cada pensamiento tú. Y yo yo me callaba yo, por no arruinarlo todo yo. Y besarte la boca, robarte la boca.
A40: =AGREEMENT!A458 -> BALADA | B40: =AGREEMENT!E458 -> QueridaCada momento de mi vidaYo pienso en ti más cada díaMira mi soledad, mira mi soledadQue no me sienta nada bien, oh ven yaQueridaNo me ha sanado bien la heridaTe extraño y lloro todavíaMira mi soledad, mira mi soledadQue no me sienta nada bien, oh ven yaQueridaPiensa en mi sólo un momento y venDate cuenta de que el tiempo es cruelY lo he pasado yo sin ti, oh ven ya
...

Sheet Testing
A1: =AGREEMENT!A1 -> CATEGORIA | B1: =AGREEMENT!E1 -> FRAGMENTO DE LETRAS DE CANCIONES (ALREDEDOR DE 30+ PALABRAS)
A2: =AGREEMENT!A114 -> BALADA | B2: =AGREEMENT!E114 -> Cuando me enamoro A veces, desespero Cuando me enamoro Y cuando menos me lo espero, me enamoro Se detiene el tiempo Me viene el alma al cuerpo Sonrío Cuando me enamoro
A3: =AGREEMENT!A43 -> BALADA | B3: =AGREEMENT!E43 -> Ana, Ana mía mi pasión y mi poesía en mis besos tus deseos ardía Ana es una extraña melodía la razón de mi alegría. Ana, Ana mía realidad y fantasía.
A4: =AGREEMENT!A301 -> REGAETTON | B4: =AGREEMENT!E301 -> Me dices que pa' qué y yo te digo que si no somos nada, ¿entonces a qué estamos jugando? El tiempo volando y tú sin mí no sé si bien la estás pasando.
A5: =AGREEMENT!A672 -> REGAETTON | B5: =AGREEMENT!E672 -> Yo no soy y ni voy a ser tu bizcochito Pero tengo to' lo que tiene delito Que me pongan en el sol, que me derrito El mal de ojo' que me manden me lo quito
A6: =AGREEMENT!A187 -> REGAETTON | B6: =AGREEMENT!E187 -> En la secundaria me doblaba la faldita. Soy una coqueta desde que era chamaquita. El del punto dice que parezco muñequita. Si me guiña el ojo, sé que quiere mi cosita. Por andar de lela reprobé un año de escuela. Yo lo que he escuchado es que le cago a la maestra. En primero me gustaba el novio de Pamela. Y lo suspendieron por caldearme en la escalera
A7: =AGREEMENT!A327 -> BALADA | B7: =AGREEMENT!E327 -> Mientes tan bien Que me sabe a verdad Todo lo que me das Ya te estoy amando Mientes tan bien Que he llegado a imaginar Que en mi amor llenas tu piel Y, aunque todo es de papel. uh-uh Mientes tan bien
A8: =AGREEMENT!A87 -> REGAETTON | B8: =AGREEMENT!E87 -> Bebecita, estás más rica que ayer (rica que ayer) Qué bueno fue volverte a ver (volverte a ver) Se ve que no te sabe querer (-er) Conmigo te ve' mejor que con él
A9: =AGREEMENT!A615 -> REGAETTON | B9: =AGREEMENT!E615 -> Y de pensar que yo contigo quiero estar Quiero probar algo de ti pa' no olvidar Yo no me sé ni su nombre (pero la quiero) Pasó y dejó su fragancia (y hasta me desesperó) Rapa-pa-pai, rapa-pa-pai (oh, oh, oh) Y rapa-pa-pai, rapa-pa-pai Así es que la quiero-quiero Rapa-pa-pai, rapa-pa-pai (oh, oh) Y rapa-pa-pai, rapa-pa-pai Así es que la quiero-quiero
A10: =AGREEMENT!A5 -> REGAETTON | B10: =AGREEMENT!E5 -> ¿Pa' qué buscar en la calle lo que abunda en mi casa? Una mamacita buena gente, qué chimba de cuerpo y de cara. Y aunque la baby es inocente y con otras se compara. Diosito la hizo humilde, pero yo la veo bien cara
A11: =AGREEMENT!A416 -> BALADA | B11: =AGREEMENT!E416 -> Por eso vete, olvida mi nombre, mi cara, mi casa Y pega la vuelta Jamás te pude comprender Vete, olvida mis ojos, mis manos, mis labios Que no te desean Estás mintiendo ya lo sé Vete, olvida que existo, que me conociste, Y no te sorprendas, olvida de todo que tú para eso Tienes experiencia
A12: =AGREEMENT!A350 -> REGAETTON | B12: =AGREEMENT!E350 -> No me importa lo que de mí se diga Viva usted su vida, que yo vivo la mía Que solo es una, disfruta el momento Que el tiempo se acaba y pa'trás no vira Bebiendo, fumando y jodiendo Sigo vacilando de party to' los día' Síguelo, oh-oh-oh, oh-oh-oh, oh-oh (Farru) Síguelo, oh-oh-oh, oh-oh-oh, oh-oh (la rola y pepa) Pepa y agua pa' la seca To' el mundo en pastilla' en la discoteca Pepa y agua pa' la seca To' el mundo en pastilla' en la discoteca
A13: =AGREEMENT!A36 -> BALADA | B13: =AGREEMENT!E36 -> Amor Si alguna vez nos vemos por ahí Invítame a un café y hazme el amor Y si ya no vuelvo a verte, ojalá que tengas suerte Ya lo ves La vida es así Tú te vas Y yo me quedo aquí
A14: =AGREEMENT!A389 -> REGAETTON | B14: =AGREEMENT!E389 -> Pa' ti naki, chicken teriyaki Tu gata quiere maki, mi gata en Kawasaki Quiero una cadena que me arruine to'a la cuenta Como Naomi en los 90 Rosa' sin tarjeta Se las mando a tu gata (ey) Te la tengo con Roleta (ey) No hizo falta serenata Pa' ti naki, chicken teriyaki Pa' ti naki, chicken teriyaki Pa' ti naki, chicken teriyaki Tu gata quiere maki (mi gata en Kawasaki) Quiero una cadena que me arruine to'a la cuenta Como Julio en los 70 (pa' ti naki, chicken teriyaki)
A15: =AGREEMENT!A25 -> BALADA | B15: =AGREEMENT!E25 -> Aléjate de mí y hazlo pronto, antes de que te mienta Tu cielo se hace gris, yo ya camino bajo la tormenta Aléjate de mí, escapa, vete, ya no debo verte Entiende que aunque pida que te vayas, no quiero perderte
A16: =AGREEMENT!A225 -> REGAETTON | B16: =AGREEMENT!E225 -> fumo y enrollo llegando a la lu ahora cierro y termino con la U mi juventud me la gozo con actitud orgulloso de mi talento y de toda mi virtud
A17: =AGREEMENT!A174 -> BALADA | B17: =AGREEMENT!E174 -> Ella es ese sueño Que tuve despierto Un recuerdo leve De esto que siento Una sacudida A mis salidas La cima de un beso en un brinco suicida Su fuente de energía Cautiva mis sensores Pues no hay que la controle Cuando baila encendía
A18: =AGREEMENT!A132 -> REGAETTON | B18: =AGREEMENT!E132 -> De mirarte a los ojos, sé cómo te siente'. Extraño la sonrisa reluciente de siempre. Todo pasa, sé paciente, habrá tiempo suficiente. Pa' sanar las herida' y borrar lo negativo de la mente. Sabes que yo, así, no puedo verte
A19: =AGREEMENT!A601 -> BALADA | B19: =AGREEMENT!E601 -> Voy a darte una segunda oportunidad. Quiero confesarte que yo nunca te dejé de amar. De mi parte, de seguro no te voy a fallar. No te pagaré con la misma moneda, yo sí sé amar.
A20: =AGREEMENT!A97 -> BALADA | B20: =AGREEMENT!E97 -> Casi todos sabemos querer Pero pocos sabemos amar Es que amar y querer no es igual Amar es sufrir querer es gozar El que ama pretende servir El que ama su vida la da Y el que quiere pretende vivir Y nunca sufrir, y nunca sufrir
A21: =AGREEMENT!A533 -> BALADA | B21: =AGREEMENT!E533 -> Te esperé, llegué a sentir que me moría Te esperé, como la luna espera el día Lo intenté, pero continuó la vida Te esperé, pero el tiempo cerró la herida
A22: =AGREEMENT!A562 -> BALADA | B22: =AGREEMENT!E562 -> Tú eres la mujer que yo he esperado tantoLa que comparte su risa y su llanto La que se entrega en alma y cuerpo La que puede darme un amor eterno Ohhh ohhh ohhh un amor eterno Por ti volvieron los colores Por ti escribo canciones Por ti aun me queda fe Por ti puedo decir que creo en el amor Solo por ti
A23: =AGREEMENT!A286 -> REGAETTON | B23: =AGREEMENT!E286 -> Mami, eres lo que quiero Cuando veo tu sonrisa Y es lo que me debilita Quiero llevarte a una cita Yo te quiero enseñar todo El amor que yo te tengo Tan sencilla que tú eres Para mí tú eres perfecta Yo te quiero amar, te quiero enseñar El amor y más Y eres perfecta Tu cuerpo hermoso que luce tan bello Y esos ojitos Ni se diga más Ni se diga más ¡Ahí te va, chiquitita!
A24: =AGREEMENT!A28 -> BALADA | B24: =AGREEMENT!E28 -> Amada mía Después de tantos años Después de tantas noches compartidas Después de tantos sueños Soñados cada día Te sigo amando tanto Amada mía Tus ojos negros Se clavan como siempre Tu beso es una llama que aún me quema Yo sigo siendo el árbol Y tú, la tierra mía Te sigo amando tanto Amada mía Amada mía Después de tantas horas De camino Tú sigues siendo playa
A25: =AGREEMENT!A9 -> REGAETTON | B25: =AGREEMENT!E9 -> ¿Qué me hizo usted? Que la quiero volver a ver Y volverla a besar Yo te paso a buscar, buscar Es que la bellaquera contigo Con nadie más la consigo De tus grito' hoy no me olvido Te-te-tengo reservao' el hotel
A26: =AGREEMENT!A45 -> BALADA | B26: =AGREEMENT!E45 -> Ansiedad, de tenerte en mis brazos, Musitando palabra de amor. Ansiedad, de tener tus encantos, Y en la boca volveré a besar........ Ansiedad, de tenerte en los brazos, musitando palabra de amor, Ansiedad de tener los encantos, Y en la boca volveré a besar. Tal vez estaré llorando mis pensamientos, Mis lágrimas son perlas que al caer al mar, Y el eco adormecido, de ese lamento
A27: =AGREEMENT!A597 -> REGAETTON | B27: =AGREEMENT!E597 -> Víveme sin miedo ahora Que sea una vida o sea una hora No me dejes libre aquí desnudo Mi nuevo espacio que ahora es tuyo, te ruego
A28: =AGREEMENT!A196 -> BALADA | B28: =AGREEMENT!E196 -> Es preciso decir que no Cuando se tiene el alma herida Porque el amor de los dos El que una vez fue el mejor hoy me lastima
A29: =AGREEMENT!A604 -> REGAETTON | B29: =AGREEMENT!E604 -> Voy buscando una lady Como tú, la quiero así Quiero que te enamores Como estoy yo de ti A casa, enviarte flores Y en tu nombre escribir Mil canciones de amores Pa' que pienses en mí Como yo pienso en ti
A30: =AGREEMENT!A229 -> REGAETTON | B30: =AGREEMENT!E229 -> Hace mucho tiempo que te quiero ver Busco la manera de tu cuerpo tener Ni tu padre ni tu madre te quieren conmigo Pues hagamos el amor por el teléfono
A31: =AGREEMENT!A112 -> BALADA | B31: =AGREEMENT!E112 -> Cuando escriba tu nombre en la arena blanca con fondo azul Cuando mire el cielo, en la forma cruel de una nube gris aparezcas tú Una tarde suba una alta loma, mire el pasado, sabrás que no te he olvidado
A32: =AGREEMENT!A73 -> REGAETTON | B32: =AGREEMENT!E73 -> Baby Suena tu canción y tú no estás aquí, a mi lao Yo sé que no debo, aunque te pienso demasiao Qué rico esos días cuando estábamos tragao' Tú y yo somos fuego cuando estamos emborrachao' Suena tu canción y tú no estás aquí, a mi lao Yo sé que no debo, aunque te pienso demasiao Quererte es tan fácil y a la vez tan complicao Mirando al teléfono, pero no me has llamao Baby, wow Me gustas demasiado Bebé Baby, wow Te pienso demasiao
A33: =AGREEMENT!A124 -> BALADA | B33: =AGREEMENT!E124 -> Cuanto daría por gritarles nuestro amor Decirles que al cerrar la puerta nos amamos sin control Que despertamos abrazados Con ganas de seguir amándonos Pero es que en realidad no aceptan nuestro amor
A34: =AGREEMENT!A555 -> BALADA | B34: =AGREEMENT!E555 -> Todo lo que pasa es relativo. Pero, cada vez que estoy contigo. El tiempo se detiene. Y desapareces. Y tú me das todo lo demás. Yo quiero estar donde tú estás. Amor eres tú. Solo tú. Y tú me das todo lo demás. Yo quiero estar donde tú estás. Amor eres tú. Ninguno como tú. Todo lo que dice un solo beso. Hace que se rinda el universo. Como hacen los dioses. Al caer la noche. Para qué correr si no hay apuro. Si es que cada vez que estamos juntos. El tiempo se detiene. Y desapareces
A35: =AGREEMENT!A594 -> BALADA | B35: =AGREEMENT!E594 -> Viejo, mi querido viejo Ahora ya caminas lerdo Como perdonando el viento Yo soy tu sangre, mi viejo Soy tu silencio y tu tiempo Él tiene los ojos buenos Y una figura pesada La edad se le vino encima Sin carnaval ni comparsa
A36: =AGREEMENT!A431 -> BALADA | B36: =AGREEMENT!E431 -> Qué difícil es hablarte y tú no comprender. Conversar lo mismo y enfadarnos otra vez. Porque no me dejas que me vaya por un tiempo. Sin decirme que al momento. Te vas a quitar la vida si me voy
A37: =AGREEMENT!A599 -> REGAETTON | B37: =AGREEMENT!E599 -> Vo'a llevarte pa' PR, mami, pa' que vea' cómo es que se perrea. Tráete a tu amiga si te gusta la idea. Dile que esta noche vamo' a janguear. Que rico la vamo' a pasar. Aquí nadie se va a casar. Pero tú te va' a querer quedar, yeah
A38: =AGREEMENT!A511 -> BALADA | B38: =AGREEMENT!E511 -> Siempre serás la niña que me llena el alma. Como un mar inquieto, como un mar en calma. Siempre tan lejana como el horizonte. Gritando en el silencio tu nombre en mis labios. Solo queda el eco de mi desengaño.
A39: =AGREEMENT!A135 -> BALADA | B39: =AGREEMENT!E135 -> Decir "te quiero", decir "amor" No significa nada Las palabras sinceras, las que tienen valor Son las que salen del alma Y en mi alma nacen Solo palabras blancas. Preguntas sin respuesta Llenas de esperanza Un amor como el mío no se puede ahogar Como una piedra en un río Un amor como el mío no se puede acabar Ni estando lejos te olvido
A40: =AGREEMENT!A74 -> REGAETTON | B40: =AGREEMENT!E74 -> Baby, ¿por qué tú sigue' ahí, tan incómoda ahí? Escápate conmigo, no' vamo' del party Tú queriendo irte y él no te deja ir (¿qué?) Tanto gym, pero él no te hace venir
...

Sheet Coeficiente de Correlación Intr
A1: Hoja A | B1: Hoja B | C1: Hoja C | D1: Desacuerdo de cada fila | F1: Promedio desacuedo | G1: Varianza total | H1: ICC | J1: Escala | K1: Interpretación
A2: =A!B2 -> -1 | B2: =B!B2 -> -2 | C2: ='C'!B2 -> -1 | D2: =_xlfn.VAR.S(A2:C2) -> 0.33333333 | F2: =AVERAGE(D2:D691) -> 0.74057971 | G2: =_xlfn.VAR.S(A2:C691) -> 3.0207793 | H2: =1 - (F2/G2) -> 0.75483819 | J2: >0.40 | K2: Pobre
A3: =A!B3 -> 2 | B3: =B!B3 -> 2 | C3: ='C'!B3 -> 2 | D3: =_xlfn.VAR.S(A3:C3) -> 0 | J3: 0.40 - 0.59 | K3: Regular
A4: =A!B4 -> -2 | B4: =B!B4 -> 0 | C4: ='C'!B4 -> -1 | D4: =_xlfn.VAR.S(A4:C4) -> 1 | J4: 0.60 - 0.74 | K4: Bueno
A5: =A!B5 -> 2 | B5: =B!B5 -> 2 | C5: ='C'!B5 -> 2 | D5: =_xlfn.VAR.S(A5:C5) -> 0 | J5: 0.75 - 1 | K5: Excelente
A6: =A!B6 -> 0 | B6: =B!B6 -> 2 | C6: ='C'!B6 -> 2 | D6: =_xlfn.VAR.S(A6:C6) -> 1.3333333
A7: =A!B7 -> 1 | B7: =B!B7 -> 0 | C7: ='C'!B7 -> 2 | D7: =_xlfn.VAR.S(A7:C7) -> 1
A8: =A!B8 -> -1 | B8: =B!B8 -> -2 | C8: ='C'!B8 -> -2 | D8: =_xlfn.VAR.S(A8:C8) -> 0.33333333
A9: =A!B9 -> 2 | B9: =B!B9 -> 2 | C9: ='C'!B9 -> 2 | D9: =_xlfn.VAR.S(A9:C9) -> 0
A10: =A!B10 -> -2 | B10: =B!B10 -> -2 | C10: ='C'!B10 -> -1 | D10: =_xlfn.VAR.S(A10:C10) -> 0.33333333
A11: =A!B11 -> -2 | B11: =B!B11 -> -2 | C11: ='C'!B11 -> 0 | D11: =_xlfn.VAR.S(A11:C11) -> 1.3333333
A12: =A!B12 -> 1 | B12: =B!B12 -> 1 | C12: ='C'!B12 -> -1 | D12: =_xlfn.VAR.S(A12:C12) -> 1.3333333
A13: =A!B13 -> 2 | B13: =B!B13 -> 2 | C13: ='C'!B13 -> 2 | D13: =_xlfn.VAR.S(A13:C13) -> 0
A14: =A!B14 -> 2 | B14: =B!B14 -> 2 | C14: ='C'!B14 -> 2 | D14: =_xlfn.VAR.S(A14:C14) -> 0
A15: =A!B15 -> 2 | B15: =B!B15 -> 2 | C15: ='C'!B15 -> 2 | D15: =_xlfn.VAR.S(A15:C15) -> 0
A16: =A!B16 -> 2 | B16: =B!B16 -> 2 | C16: ='C'!B16 -> 2 | D16: =_xlfn.VAR.S(A16:C16) -> 0
A17: =A!B17 -> 2 | B17: =B!B17 -> 1 | C17: ='C'!B17 -> 2 | D17: =_xlfn.VAR.S(A17:C17) -> 0.33333333
... A691: =A!B691 -> 2 | B691: =B!B691 -> 2 | C691: ='C'!B691 -> 2 | D691: =_xlfn.VAR.S(A691:C691) -> 0
A692: =A!B692
A693: =A!B693
